ERROR 2025-07-10 01:31:22,022 exceptions API Error: {'detail': ErrorDetail(string='Authentication credentials were not provided.', code='not_authenticated'), 'status_code': 401}
WARNING 2025-07-10 01:31:22,024 log Unauthorized: /api/auth/me/
ERROR 2025-07-10 01:41:28,720 exceptions API Error: {'detail': ErrorDetail(string='No active account found with the given credentials', code='no_active_account'), 'status_code': 401}
WARNING 2025-07-10 01:41:28,721 log Unauthorized: /api/auth/token/
ERROR 2025-07-10 01:41:54,971 exceptions Unhandled Exception: Incompatible AutoSchema used on View <class 'users.views.UserProfileView'>. Is DRF's DEFAULT_SCHEMA_CLASS pointing to "drf_spectacular.openapi.AutoSchema" or any other drf-spectacular compatible AutoSchema?
Traceback (most recent call last):
  File "/usr/local/lib/python3.11/site-packages/rest_framework/views.py", line 506, in dispatch
    response = handler(request, *args, **kwargs)
               ^^^^^^^^^^^^^^^^^^^^^^^^^^^^^^^^^
  File "/usr/local/lib/python3.11/site-packages/drf_spectacular/views.py", line 84, in get
    return self._get_schema_response(request)
           ^^^^^^^^^^^^^^^^^^^^^^^^^^^^^^^^^^
  File "/usr/local/lib/python3.11/site-packages/drf_spectacular/views.py", line 92, in _get_schema_response
    data=generator.get_schema(request=request, public=self.serve_public),
         ^^^^^^^^^^^^^^^^^^^^^^^^^^^^^^^^^^^^^^^^^^^^^^^^^^^^^^^^^^^^^^^
  File "/usr/local/lib/python3.11/site-packages/drf_spectacular/generators.py", line 285, in get_schema
    paths=self.parse(request, public),
          ^^^^^^^^^^^^^^^^^^^^^^^^^^^
  File "/usr/local/lib/python3.11/site-packages/drf_spectacular/generators.py", line 250, in parse
    assert isinstance(view.schema, AutoSchema), (
           ^^^^^^^^^^^^^^^^^^^^^^^^^^^^^^^^^^^
AssertionError: Incompatible AutoSchema used on View <class 'users.views.UserProfileView'>. Is DRF's DEFAULT_SCHEMA_CLASS pointing to "drf_spectacular.openapi.AutoSchema" or any other drf-spectacular compatible AutoSchema?
ERROR 2025-07-10 01:41:54,999 log Internal Server Error: /api/schema/
Traceback (most recent call last):
  File "/usr/local/lib/python3.11/site-packages/django/core/handlers/exception.py", line 55, in inner
    response = get_response(request)
               ^^^^^^^^^^^^^^^^^^^^^
  File "/usr/local/lib/python3.11/site-packages/django/core/handlers/base.py", line 197, in _get_response
    response = wrapped_callback(request, *callback_args, **callback_kwargs)
               ^^^^^^^^^^^^^^^^^^^^^^^^^^^^^^^^^^^^^^^^^^^^^^^^^^^^^^^^^^^^
  File "/usr/local/lib/python3.11/site-packages/django/views/decorators/csrf.py", line 65, in _view_wrapper
    return view_func(request, *args, **kwargs)
           ^^^^^^^^^^^^^^^^^^^^^^^^^^^^^^^^^^^
  File "/usr/local/lib/python3.11/site-packages/django/views/generic/base.py", line 104, in view
    return self.dispatch(request, *args, **kwargs)
           ^^^^^^^^^^^^^^^^^^^^^^^^^^^^^^^^^^^^^^^
  File "/usr/local/lib/python3.11/site-packages/rest_framework/views.py", line 509, in dispatch
    response = self.handle_exception(exc)
               ^^^^^^^^^^^^^^^^^^^^^^^^^^
  File "/usr/local/lib/python3.11/site-packages/rest_framework/views.py", line 469, in handle_exception
    self.raise_uncaught_exception(exc)
  File "/usr/local/lib/python3.11/site-packages/rest_framework/views.py", line 480, in raise_uncaught_exception
    raise exc
  File "/usr/local/lib/python3.11/site-packages/rest_framework/views.py", line 506, in dispatch
    response = handler(request, *args, **kwargs)
               ^^^^^^^^^^^^^^^^^^^^^^^^^^^^^^^^^
  File "/usr/local/lib/python3.11/site-packages/drf_spectacular/views.py", line 84, in get
    return self._get_schema_response(request)
           ^^^^^^^^^^^^^^^^^^^^^^^^^^^^^^^^^^
  File "/usr/local/lib/python3.11/site-packages/drf_spectacular/views.py", line 92, in _get_schema_response
    data=generator.get_schema(request=request, public=self.serve_public),
         ^^^^^^^^^^^^^^^^^^^^^^^^^^^^^^^^^^^^^^^^^^^^^^^^^^^^^^^^^^^^^^^
  File "/usr/local/lib/python3.11/site-packages/drf_spectacular/generators.py", line 285, in get_schema
    paths=self.parse(request, public),
          ^^^^^^^^^^^^^^^^^^^^^^^^^^^
  File "/usr/local/lib/python3.11/site-packages/drf_spectacular/generators.py", line 250, in parse
    assert isinstance(view.schema, AutoSchema), (
           ^^^^^^^^^^^^^^^^^^^^^^^^^^^^^^^^^^^
AssertionError: Incompatible AutoSchema used on View <class 'users.views.UserProfileView'>. Is DRF's DEFAULT_SCHEMA_CLASS pointing to "drf_spectacular.openapi.AutoSchema" or any other drf-spectacular compatible AutoSchema?
ERROR 2025-07-10 01:41:55,024 exceptions Unhandled Exception: Incompatible AutoSchema used on View <class 'users.views.UserProfileView'>. Is DRF's DEFAULT_SCHEMA_CLASS pointing to "drf_spectacular.openapi.AutoSchema" or any other drf-spectacular compatible AutoSchema?
Traceback (most recent call last):
  File "/usr/local/lib/python3.11/site-packages/rest_framework/views.py", line 506, in dispatch
    response = handler(request, *args, **kwargs)
               ^^^^^^^^^^^^^^^^^^^^^^^^^^^^^^^^^
  File "/usr/local/lib/python3.11/site-packages/drf_spectacular/views.py", line 84, in get
    return self._get_schema_response(request)
           ^^^^^^^^^^^^^^^^^^^^^^^^^^^^^^^^^^
  File "/usr/local/lib/python3.11/site-packages/drf_spectacular/views.py", line 92, in _get_schema_response
    data=generator.get_schema(request=request, public=self.serve_public),
         ^^^^^^^^^^^^^^^^^^^^^^^^^^^^^^^^^^^^^^^^^^^^^^^^^^^^^^^^^^^^^^^
  File "/usr/local/lib/python3.11/site-packages/drf_spectacular/generators.py", line 285, in get_schema
    paths=self.parse(request, public),
          ^^^^^^^^^^^^^^^^^^^^^^^^^^^
  File "/usr/local/lib/python3.11/site-packages/drf_spectacular/generators.py", line 250, in parse
    assert isinstance(view.schema, AutoSchema), (
           ^^^^^^^^^^^^^^^^^^^^^^^^^^^^^^^^^^^
AssertionError: Incompatible AutoSchema used on View <class 'users.views.UserProfileView'>. Is DRF's DEFAULT_SCHEMA_CLASS pointing to "drf_spectacular.openapi.AutoSchema" or any other drf-spectacular compatible AutoSchema?
ERROR 2025-07-10 01:41:55,037 log Internal Server Error: /api/schema/
Traceback (most recent call last):
  File "/usr/local/lib/python3.11/site-packages/django/core/handlers/exception.py", line 55, in inner
    response = get_response(request)
               ^^^^^^^^^^^^^^^^^^^^^
  File "/usr/local/lib/python3.11/site-packages/django/core/handlers/base.py", line 197, in _get_response
    response = wrapped_callback(request, *callback_args, **callback_kwargs)
               ^^^^^^^^^^^^^^^^^^^^^^^^^^^^^^^^^^^^^^^^^^^^^^^^^^^^^^^^^^^^
  File "/usr/local/lib/python3.11/site-packages/django/views/decorators/csrf.py", line 65, in _view_wrapper
    return view_func(request, *args, **kwargs)
           ^^^^^^^^^^^^^^^^^^^^^^^^^^^^^^^^^^^
  File "/usr/local/lib/python3.11/site-packages/django/views/generic/base.py", line 104, in view
    return self.dispatch(request, *args, **kwargs)
           ^^^^^^^^^^^^^^^^^^^^^^^^^^^^^^^^^^^^^^^
  File "/usr/local/lib/python3.11/site-packages/rest_framework/views.py", line 509, in dispatch
    response = self.handle_exception(exc)
               ^^^^^^^^^^^^^^^^^^^^^^^^^^
  File "/usr/local/lib/python3.11/site-packages/rest_framework/views.py", line 469, in handle_exception
    self.raise_uncaught_exception(exc)
  File "/usr/local/lib/python3.11/site-packages/rest_framework/views.py", line 480, in raise_uncaught_exception
    raise exc
  File "/usr/local/lib/python3.11/site-packages/rest_framework/views.py", line 506, in dispatch
    response = handler(request, *args, **kwargs)
               ^^^^^^^^^^^^^^^^^^^^^^^^^^^^^^^^^
  File "/usr/local/lib/python3.11/site-packages/drf_spectacular/views.py", line 84, in get
    return self._get_schema_response(request)
           ^^^^^^^^^^^^^^^^^^^^^^^^^^^^^^^^^^
  File "/usr/local/lib/python3.11/site-packages/drf_spectacular/views.py", line 92, in _get_schema_response
    data=generator.get_schema(request=request, public=self.serve_public),
         ^^^^^^^^^^^^^^^^^^^^^^^^^^^^^^^^^^^^^^^^^^^^^^^^^^^^^^^^^^^^^^^
  File "/usr/local/lib/python3.11/site-packages/drf_spectacular/generators.py", line 285, in get_schema
    paths=self.parse(request, public),
          ^^^^^^^^^^^^^^^^^^^^^^^^^^^
  File "/usr/local/lib/python3.11/site-packages/drf_spectacular/generators.py", line 250, in parse
    assert isinstance(view.schema, AutoSchema), (
           ^^^^^^^^^^^^^^^^^^^^^^^^^^^^^^^^^^^
AssertionError: Incompatible AutoSchema used on View <class 'users.views.UserProfileView'>. Is DRF's DEFAULT_SCHEMA_CLASS pointing to "drf_spectacular.openapi.AutoSchema" or any other drf-spectacular compatible AutoSchema?
ERROR 2025-07-10 01:43:18,241 exceptions API Error: {'detail': ErrorDetail(string='No active account found with the given credentials', code='no_active_account'), 'status_code': 401}
WARNING 2025-07-10 01:43:18,242 log Unauthorized: /api/auth/token/
ERROR 2025-07-10 02:24:03,383 exceptions API Error: {'detail': ErrorDetail(string='No active account found with the given credentials', code='no_active_account'), 'status_code': 401}
WARNING 2025-07-10 02:24:03,391 log Unauthorized: /api/auth/token/
ERROR 2025-07-10 02:25:53,971 exceptions API Error: {'detail': ErrorDetail(string='Authentication credentials were not provided.', code='not_authenticated'), 'status_code': 401}
WARNING 2025-07-10 02:25:53,971 log Unauthorized: /api/auth/me/
ERROR 2025-07-12 01:04:53,161 exceptions API Error: {'detail': ErrorDetail(string='Authentication credentials were not provided.', code='not_authenticated'), 'status_code': 401}
WARNING 2025-07-12 01:04:53,162 log Unauthorized: /api/auth/me/
ERROR 2025-07-12 01:50:43,244 exceptions API Error: {'detail': ErrorDetail(string='Authentication credentials were not provided.', code='not_authenticated'), 'status_code': 401}
WARNING 2025-07-12 01:50:43,251 log Unauthorized: /api/data/periodic-table/
ERROR 2025-07-12 01:50:52,822 exceptions API Error: {'detail': ErrorDetail(string='Authentication credentials were not provided.', code='not_authenticated'), 'status_code': 401}
WARNING 2025-07-12 01:50:52,823 log Unauthorized: /api/data/periodic-table/
ERROR 2025-07-12 01:50:52,833 exceptions API Error: {'detail': ErrorDetail(string='Authentication credentials were not provided.', code='not_authenticated'), 'status_code': 401}
WARNING 2025-07-12 01:50:52,834 log Unauthorized: /api/data/periodic-table/
ERROR 2025-07-12 02:56:28,716 exceptions API Error: {'name': [ErrorDetail(string='This field may not be blank.', code='blank')], 'structure_data': [ErrorDetail(string='This field may not be blank.', code='blank')], 'status_code': 400}
WARNING 2025-07-12 02:56:28,719 log Bad Request: /api/molecules/
ERROR 2025-07-12 02:56:36,357 exceptions API Error: {'detail': ErrorDetail(string='Authentication credentials were not provided.', code='not_authenticated'), 'status_code': 401}
WARNING 2025-07-12 02:56:36,364 log Unauthorized: /api/data/periodic-table/
ERROR 2025-07-12 02:56:46,801 exceptions API Error: {'password': [ErrorDetail(string='This field may not be blank.', code='blank')], 'status_code': 400}
WARNING 2025-07-12 02:56:46,802 log Bad Request: /api/auth/token/
ERROR 2025-07-12 02:56:57,850 exceptions API Error: {'detail': ErrorDetail(string='No active account found with the given credentials', code='no_active_account'), 'status_code': 401}
WARNING 2025-07-12 02:56:57,850 log Unauthorized: /api/auth/token/
ERROR 2025-07-12 02:58:44,306 exceptions API Error: {'name': [ErrorDetail(string='This field may not be blank.', code='blank')], 'structure_data': [ErrorDetail(string='This field may not be blank.', code='blank')], 'status_code': 400}
WARNING 2025-07-12 02:58:44,306 log Bad Request: /api/molecules/
ERROR 2025-07-12 03:00:51,658 exceptions API Error: {'detail': ErrorDetail(string='Authentication credentials were not provided.', code='not_authenticated'), 'status_code': 401}
WARNING 2025-07-12 03:00:51,659 log Unauthorized: /api/data/periodic-table/
ERROR 2025-07-12 03:00:55,785 exceptions API Error: {'detail': ErrorDetail(string='Authentication credentials were not provided.', code='not_authenticated'), 'status_code': 401}
WARNING 2025-07-12 03:00:55,787 log Unauthorized: /api/data/periodic-table/
ERROR 2025-07-12 03:00:55,792 exceptions API Error: {'detail': ErrorDetail(string='Authentication credentials were not provided.', code='not_authenticated'), 'status_code': 401}
WARNING 2025-07-12 03:00:55,793 log Unauthorized: /api/data/periodic-table/
ERROR 2025-07-12 16:30:21,411 exceptions API Error: {'detail': ErrorDetail(string='Given token not valid for any token type', code='token_not_valid'), 'code': ErrorDetail(string='token_not_valid', code='token_not_valid'), 'messages': [{'token_class': ErrorDetail(string='AccessToken', code='token_not_valid'), 'token_type': ErrorDetail(string='access', code='token_not_valid'), 'message': ErrorDetail(string='Token is invalid or expired', code='token_not_valid')}], 'status_code': 401}
WARNING 2025-07-12 16:30:21,442 log Unauthorized: /api/data/periodic-table/
ERROR 2025-07-12 16:30:21,452 exceptions API Error: {'detail': ErrorDetail(string='Given token not valid for any token type', code='token_not_valid'), 'code': ErrorDetail(string='token_not_valid', code='token_not_valid'), 'messages': [{'token_class': ErrorDetail(string='AccessToken', code='token_not_valid'), 'token_type': ErrorDetail(string='access', code='token_not_valid'), 'message': ErrorDetail(string='Token is invalid or expired', code='token_not_valid')}], 'status_code': 401}
WARNING 2025-07-12 16:30:21,453 log Unauthorized: /api/data/periodic-table/
ERROR 2025-07-12 16:30:33,935 exceptions API Error: {'detail': ErrorDetail(string='Authentication credentials were not provided.', code='not_authenticated'), 'status_code': 401}
WARNING 2025-07-12 16:30:33,935 log Unauthorized: /api/data/periodic-table/
ERROR 2025-07-18 01:31:05,194 exceptions API Error: {'detail': ErrorDetail(string='No active account found with the given credentials', code='no_active_account'), 'status_code': 401}
WARNING 2025-07-18 01:31:05,195 log Unauthorized: /api/auth/token/
ERROR 2025-07-18 01:31:05,208 exceptions API Error: {'detail': ErrorDetail(string='Authentication credentials were not provided.', code='not_authenticated'), 'status_code': 401}
WARNING 2025-07-18 01:31:05,208 log Unauthorized: /api/telemetry/log/
ERROR 2025-07-18 01:31:45,262 exceptions API Error: {'structure_data': [ErrorDetail(string='La cadena SMILES proporcionada no es válida.', code='invalid')], 'status_code': 400}
WARNING 2025-07-18 01:31:45,262 log Bad Request: /api/molecules/
WARNING 2025-07-18 01:32:09,622 log Bad Request: /api/calculate/molecular-weight/
WARNING 2025-07-18 01:32:29,400 log Bad Request: /api/calculate/molecular-weight/
